Workbook

Sheet How to Use
B1: BA Services – AI Prompt Library (CARE + G.E.T.) — v1.0
B2: Portable edition • 126 prompts across 42 L3 BA services and 6 roles • Organisation-neutral: no client names, sectors or jurisdiction-specific rules — adapt the worked examples to your own domain
B4: What's in this workbook
B5: Prompt Library | C5: One Master prompt per L3 BA service plus Deliverable prompts for key deliverables — 126 prompts across Business BA (8 services), Business/Tech BA (9), Technical BA (6), Agile BA (6), Lead BA (6) and Practice Lead (7). Copy the 'Full Prompt (copy-paste)' cell and replace [BRACKETED PLACEHOLDERS].
B6: Prompt Scores | C6: Every prompt scored against the 10-criterion quality scorecard, with deduction notes and live summary stats.
B7: Quality Scorecard | C7: The rubric itself (blank, ready to score any new prompt) with bands and the worked example.
B8: Delivery Contexts | C8: The 11 delivery contexts (system update, agile, transition, procurement, data warehouse, AI agentic, leadership...) mapped to the services and prompt IDs most used in each — start here if you know your project type but not which prompt you need.
B11: The CARE framework + G.E.T. validation
B12: C – Context | C12: Who am I, who is the audience, plus my organisation's constraints and the data-safety rule (de-identified or synthetic inputs only).
B13: A – Action | C13: One clear task with named inputs, plus 'ask me up to 5 clarifying questions first'.
B14: R – Result/Format | C14: Exact sections, tables and flags — checkable. Includes the no-invention rule: unverified = [TBC], proposed values = [PROPOSED — VALIDATE].
B15: E – Example | C15: A concrete sample the AI can imitate — every prompt has a hand-written one.
B16: G.E.T. | C16: Every prompt ends with Generate → Explain (break down the synthesis logic) → Test (list sources, cross-reference facts, list assumptions).
B18: Version history
B19: v0.1 → v0.2 | C19: First pass in CO-STAR (66 prompts, 22 services); reframed to CARE + G.E.T. per training feedback; quality scorecard added; all prompts scored (mean 18.1).
B20: v0.2 → v0.3 | C20: Extended to the 42-service L3 catalogue (+60 prompts for Strategic Advisory, Agile BA, Lead BA, Practice Lead); AI Transformation and Data & Reporting masters enriched; template hardened with in-prompt data-safety and no-invention rules (the two systematic deductions from the v0.2 scoring) — mean score now 19.7.
B21: v0.3 → v1.0 | C21: Portable edition. All organisation-specific content removed: employer identity, sector framing, named legislation and standards replaced with neutral equivalents, and every worked example rewritten in a generic case-management / service-request domain. Scores unchanged — the CARE structure, validation steps and level of concreteness are identical.
B22: Library statistics (live formulas)
B23: Total prompts | C23: =COUNTA('Prompt Library'!A2:A200) -> 126
B24: Master prompts | C24: =COUNTIF('Prompt Library'!E2:E200,"Master") -> 42
B25: Deliverable prompts | C25: =COUNTIF('Prompt Library'!E2:E200,"Deliverable") -> 84
B26: Services covered | C26: =SUMPRODUCT(('Prompt Library'!C2:C127<>"")/COUNTIF('Prompt Library'!C2:C127,'Prompt Library'!C2:C127&"")) -> 42
B27: Average quality score | C27: =ROUND(AVERAGE('Prompt Scores'!O2:O127),2) -> 19.67
B29: Adapting this library | C29: Two edits make the library organisation-specific again: (1) add your organisation and sector to the [PROJECT NAME AND ONE-LINE DESCRIPTION] placeholder or extend the # CONTEXT block; (2) replace the worked example in each # EXAMPLE block with one from your own domain — the example is what most shapes output quality. Name your privacy, security and residency obligations explicitly where the prompts refer to them generically.

Sheet Prompt Library
A1: ID | B1: Role | C1: BA Service | D1: Prompt Name | E1: Type | F1: Target Deliverable(s) | G1: C – Context | H1: A – Action | I1: R – Result/Format | J1: E – Example | K1: Validation (G.E.T.) | L1: Full Prompt (copy-paste)
A2: BB-01-M | B2: Business BA | C2: Benefits Realisation & KPI Management | D2: Master – Benefits Realisation & KPI Management | E2: Master | F2: Benefits Measures; KPI Reports; Value Realisation Assessments | G2: I am a business analyst (Business BA). I am working on [PROJECT NAME AND ONE-LINE DESCRIPTION]. My work must respect my organisation's privacy, information-security and data-residency obligations. Everything I paste is de-identified or synthetic — if any input appears to contain real personal or sensitive data, stop and alert me before proceeding. The initiative's stated benefits are: [LIST EXPECTED BENEFITS FROM THE BUSINESS CASE]. Current measurement baseline: [WHAT IS MEASURED TODAY, OR 'UNKNOWN']. The audience for this output: Benefit owners, the project sponsor and the PMO; summaries may be lifted into executive and board reporting. | H2: Act as my analysis partner for benefits realisation: define measurable benefits, design the KPIs and measures that evidence them, and assess whether value is actually being delivered, so the organisation can report outcomes credibly and identify optimisation opportunities. Produce, as I request them: (1) a benefits map linking initiative outputs to outcomes to benefits; (2) a KPI definition table (KPI, definition, formula, baseline, target, data source, frequency, owner); (3) a value realisation assessment comparing actuals to targets with root causes and optimisation recommendations. Before drafting, ask me up to 5 clarifying questions about anything missing, then wait for my answers. | I2: Structured, evidence-based business analysis writing aligned to BABOK good practice. Use clear headings, numbered requirements and tables where they aid scanning. Plain English; expand every acronym on first use; no marketing language. Every benefit must trace to a measurable KPI with a baseline, target, data source and owner. Keep the language professional, plain-English and appropriate for a business audience. Do not invent facts or figures: mark anything you could not verify from my inputs as [TBC] and any value you propose yourself as [PROPOSED — VALIDATE]. Treat the output as a first draft for my review, not a finished artefact. | J2: Example KPI row I expect: "KPI: Median case determination time | Definition: calendar days from case lodgement to final decision | Formula: median(decision_date − lodgement_date) | Baseline: 14.2 days (FY25) | Target: 10 days by Jun 2027 | Source: case management system | Frequency: monthly | Owner: Operations Manager". | K2: Generate: produce the output requested above. Explain: then break down, step by step, the logic you used to synthesise your answer — how you interpreted each of my inputs and why you structured the output the way you did. Test: list the source references you used for your analysis (my pasted inputs, earlier turns in this conversation, or your general knowledge — label which is which); cross-reference the key facts in your output against those sources and flag anything that does not trace back to a source; and list every additional assumption you made in your interpretation so I can verify or correct it. | L2: # CONTEXT I am a business analyst (Business BA). I am working on [PROJECT NAME AND ONE-LINE DESCRIPTION]. My work must respect my organisation's privacy, information-security and data-residency obligations. Everything I paste is de-identified or synthetic — if any input appears to contain real personal or sensitive data, stop and alert me before proceeding. The initiative's stated benefits are: [LIST EXPECTED BENEFITS FROM THE BUSINESS CASE]. Current measurement baseline: [WHAT IS MEASURED TODAY, OR 'UNKNOWN']. The audience for this output: Benefit owners, the project sponsor and the PMO; summaries may be lifted into executive and board reporting. # ACTION Act as my analysis partner for benefits realisation: define measurable benefits, design the KPIs and measures that evidence them, and assess whether value is actually being delivered, so the organisation can report outcomes credibly and identify optimisation opportunities. Produce, as I request them: (1) a benefits map linking initiative outputs to outcomes to benefits; (2) a KPI definition table (KPI, definition, formula, baseline, target, data source, frequency, owner); (3) a value realisation assessment comparing actuals to targets with root causes and optimisation recommendations. Before drafting, ask me up to 5 clarifying questions about anything missing, then wait for my answers. # RESULT / FORMAT Structured, evidence-based business analysis writing aligned to BABOK good practice. Use clear headings, numbered requirements and tables where they aid scanning. Plain English; expand every acronym on first use; no marketing language. Every benefit must trace to a measurable KPI with a baseline, target, data source and owner. Keep the language professional, plain-English and appropriate for a business audience. Do not invent facts or figures: mark anything you could not verify from my inputs as [TBC] and any value you propose yourself as [PROPOSED — VALIDATE]. Treat the output as a first draft for my review, not a finished artefact. # EXAMPLE Example KPI row I expect: "KPI: Median case determination time | Definition: calendar days from case lodgement to final decision | Formula: median(decision_date − lodgement_date) | Baseline: 14.2 days (FY25) | Target: 10 days by Jun 2027 | Source: case management system | Frequency: monthly | Owner: Operations Manager". # VALIDATION (GENERATE → EXPLAIN → TEST) Generate: produce the output requested above. Explain: then break down, step by step, the logic you used to synthesise your answer — how you interpreted each of my inputs and why you structured the output the way you did. Test: list the source references you used for your analysis (my pasted inputs, earlier turns in this conversation, or your general knowledge — label which is which); cross-reference the key facts in your output against those sources and flag anything that does not trace back to a source; and list every additional assumption you made in your interpretation so I can verify or correct it.
A3: BB-01-D1 | B3: Business BA | C3: Benefits Realisation & KPI Management | D3: KPI Definitions & Measures Table | E3: Deliverable | F3: Benefits Measures; KPI Definitions | G3: I am a business analyst (Business BA). I am working on [PROJECT NAME AND ONE-LINE DESCRIPTION]. My work must respect my organisation's privacy, information-security and data-residency obligations. Everything I paste is de-identified or synthetic — if any input appears to contain real personal or sensitive data, stop and alert me before proceeding. Benefits to be measured: [PASTE BENEFITS STATEMENTS OR BUSINESS CASE EXTRACT]. The audience for this output: Benefit owners and the reporting/data team who must build the measures. | H3: Turn the listed benefits into a rigorous KPI definition table that reporting teams could implement without further interpretation. Draft the table, then list measurement risks (gaming, lag, data quality) per KPI. Before drafting, ask me up to 5 clarifying questions about anything missing, then wait for my answers. | I3: One table, one row per KPI: KPI name; plain-English definition; calculation formula; unit; baseline; target and target date; data source system; collection frequency; accountable owner (role, not name). Flag any KPI that cannot currently be measured. Keep the language professional, plain-English and appropriate for a business audience. Do not invent facts or figures: mark anything you could not verify from my inputs as [TBC] and any value you propose yourself as [PROPOSED — VALIDATE]. Treat the output as a first draft for my review, not a finished artefact. | J3: Example row: "KPI: Cases resolved within 26 weeks | Definition: % of accepted cases closed within 26 weeks of lodgement | Formula: (cases closed ≤26wks ÷ accepted cases) × 100 | Baseline: [TO BE QUANTIFIED] | Target: +3pp on baseline | Source: case management system | Frequency: quarterly | Owner: Service Delivery Lead". | K3: Generate: produce the output requested above. Explain: then break down, step by step, the logic you used to synthesise your answer — how you interpreted each of my inputs and why you structured the output the way you did. Test: list the source references you used for your analysis (my pasted inputs, earlier turns in this conversation, or your general knowledge — label which is which); cross-reference the key facts in your output against those sources and flag anything that does not trace back to a source; and list every additional assumption you made in your interpretation so I can verify or correct it. | L3: # CONTEXT I am a business analyst (Business BA). I am working on [PROJECT NAME AND ONE-LINE DESCRIPTION]. My work must respect my organisation's privacy, information-security and data-residency obligations. Everything I paste is de-identified or synthetic — if any input appears to contain real personal or sensitive data, stop and alert me before proceeding. Benefits to be measured: [PASTE BENEFITS STATEMENTS OR BUSINESS CASE EXTRACT]. The audience for this output: Benefit owners and the reporting/data team who must build the measures. # ACTION Turn the listed benefits into a rigorous KPI definition table that reporting teams could implement without further interpretation. Draft the table, then list measurement risks (gaming, lag, data quality) per KPI. Before drafting, ask me up to 5 clarifying questions about anything missing, then wait for my answers. # RESULT / FORMAT One table, one row per KPI: KPI name; plain-English definition; calculation formula; unit; baseline; target and target date; data source system; collection frequency; accountable owner (role, not name). Flag any KPI that cannot currently be measured. Keep the language professional, plain-English and appropriate for a business audience. Do not invent facts or figures: mark anything you could not verify from my inputs as [TBC] and any value you propose yourself as [PROPOSED — VALIDATE]. Treat the output as a first draft for my review, not a finished artefact. # EXAMPLE Example row: "KPI: Cases resolved within 26 weeks | Definition: % of accepted cases closed within 26 weeks of lodgement | Formula: (cases closed ≤26wks ÷ accepted cases) × 100 | Baseline: [TO BE QUANTIFIED] | Target: +3pp on baseline | Source: case management system | Frequency: quarterly | Owner: Service Delivery Lead". # VALIDATION (GENERATE → EXPLAIN → TEST) Generate: produce the output requested above. Explain: then break down, step by step, the logic you used to synthesise your answer — how you interpreted each of my inputs and why you structured the output the way you did. Test: list the source references you used for your analysis (my pasted inputs, earlier turns in this conversation, or your general knowledge — label which is which); cross-reference the key facts in your output against those sources and flag anything that does not trace back to a source; and list every additional assumption you made in your interpretation so I can verify or correct it.
A4: BB-01-D2 | B4: Business BA | C4: Benefits Realisation & KPI Management | D4: Value Realisation Assessment | E4: Deliverable | F4: Value Realisation Assessments; KPI Reports | G4: I am a business analyst (Business BA). I am working on [PROJECT NAME AND ONE-LINE DESCRIPTION]. My work must respect my organisation's privacy, information-security and data-residency obligations. Everything I paste is de-identified or synthetic — if any input appears to contain real personal or sensitive data, stop and alert me before proceeding. Planned benefits and targets: [PASTE]. Actual results to date: [PASTE KPI ACTUALS / EXTRACT]. The audience for this output: Sponsor and steering committee. | H4: Assess realised value against plan, explain variances, and recommend optimisation actions. Draft the assessment (max 2 pages equivalent). Where data is insufficient to judge a benefit, say so explicitly rather than inferring success. Before drafting, ask me up to 5 clarifying questions about anything missing, then wait for my answers. | I4: Short report: RAG summary table per benefit; variance analysis; root causes distinguished from symptoms; prioritised recommendations with owner and effort estimate. Keep the language professional, plain-English and appropriate for a business audience. Do not invent facts or figures: mark anything you could not verify from my inputs as [TBC] and any value you propose yourself as [PROPOSED — VALIDATE]. Treat the output as a first draft for my review, not a finished artefact. | J4: Example variance line: "Benefit B2 – Reduced manual rework: AMBER. Target 30% reduction; actual 12%. Root cause: exception queue still routed to legacy team (process, not system). Recommendation: extend auto-routing rules to exception types 3–5; owner: Ops Improvement; effort: low." | K4: Generate: produce the output requested above. Explain: then break down, step by step, the logic you used to synthesise your answer — how you interpreted each of my inputs and why you structured the output the way you did. Test: list the source references you used for your analysis (my pasted inputs, earlier turns in this conversation, or your general knowledge — label which is which); cross-reference the key facts in your output against those sources and flag anything that does not trace back to a source; and list every additional assumption you made in your interpretation so I can verify or correct it. | L4: # CONTEXT I am a business analyst (Business BA). I am working on [PROJECT NAME AND ONE-LINE DESCRIPTION]. My work must respect my organisation's privacy, information-security and data-residency obligations. Everything I paste is de-identified or synthetic — if any input appears to contain real personal or sensitive data, stop and alert me before proceeding. Planned benefits and targets: [PASTE]. Actual results to date: [PASTE KPI ACTUALS / EXTRACT]. The audience for this output: Sponsor and steering committee. # ACTION Assess realised value against plan, explain variances, and recommend optimisation actions. Draft the assessment (max 2 pages equivalent). Where data is insufficient to judge a benefit, say so explicitly rather than inferring success. Before drafting, ask me up to 5 clarifying questions about anything missing, then wait for my answers. # RESULT / FORMAT Short report: RAG summary table per benefit; variance analysis; root causes distinguished from symptoms; prioritised recommendations with owner and effort estimate. Keep the language professional, plain-English and appropriate for a business audience. Do not invent facts or figures: mark anything you could not verify from my inputs as [TBC] and any value you propose yourself as [PROPOSED — VALIDATE]. Treat the output as a first draft for my review, not a finished artefact. # EXAMPLE Example variance line: "Benefit B2 – Reduced manual rework: AMBER. Target 30% reduction; actual 12%. Root cause: exception queue still routed to legacy team (process, not system). Recommendation: extend auto-routing rules to exception types 3–5; owner: Ops Improvement; effort: low." # VALIDATION (GENERATE → EXPLAIN → TEST) Generate: produce the output requested above. Explain: then break down, step by step, the logic you used to synthesise your answer — how you interpreted each of my inputs and why you structured the output the way you did. Test: list the source references you used for your analysis (my pasted inputs, earlier turns in this conversation, or your general knowledge — label which is which); cross-reference the key facts in your output against those sources and flag anything that does not trace back to a source; and list every additional assumption you made in your interpretation so I can verify or correct it.
A5: BB-02-M | B5: Business BA | C5: Business Needs Assessments (Initial and High Level Requirements) | D5: Master – Business Needs Assessment | E5: Master | F5: Discovery Notes; Workshop Outputs; Business Needs Statements | G5: I am a business analyst (Business BA). I am working on [PROJECT NAME AND ONE-LINE DESCRIPTION]. My work must respect my organisation's privacy, information-security and data-residency obligations. Everything I paste is de-identified or synthetic — if any input appears to contain real personal or sensitive data, stop and alert me before proceeding. Discovery stage: [NEW INITIATIVE / EXISTING PROBLEM]. What we know so far: [PASTE ANY BRIEFS, EMAILS OR NOTES]. The audience for this output: Business stakeholders and SMEs contributing needs; outputs feed the project brief and requirements backlog. | H5: Support end-to-end elicitation of business needs and high-level requirements: plan discovery sessions, generate strong questions, convert raw notes into structured needs statements, and expose conflicts and gaps between stakeholders. Support these modes on request: (1) workshop/interview plan with 8-12 questions sequenced broad-to-specific including conflict-testing questions; (2) structure raw notes into business needs statements ('The business needs the ability to [capability] so that [outcome]'); (3) simulate a named stakeholder so I can practise elicitation, then critique which questions I missed. Before drafting, ask me up to 5 clarifying questions about anything missing, then wait for my answers. | I5: Structured, evidence-based business analysis writing aligned to BABOK good practice. Use clear headings, numbered requirements and tables where they aid scanning. Plain English; expand every acronym on first use; no marketing language. Distinguish clearly between (a) explicit stakeholder statements, (b) implied needs, and (c) items needing clarification, with source attribution. Keep the language professional, plain-English and appropriate for a business audience. Do not invent facts or figures: mark anything you could not verify from my inputs as [TBC] and any value you propose yourself as [PROPOSED — VALIDATE]. Treat the output as a first draft for my review, not a finished artefact. | J5: Example needs statement I expect: "The business needs the ability to see all open actions for a customer across cases and enquiries in one view, so that staff do not request information the customer has already provided." | K5: Generate: produce the output requested above. Explain: then break down, step by step, the logic you used to synthesise your answer — how you interpreted each of my inputs and why you structured the output the way you did. Test: list the source references you used for your analysis (my pasted inputs, earlier turns in this conversation, or your general knowledge — label which is which); cross-reference the key facts in your output against those sources and flag anything that does not trace back to a source; and list every additional assumption you made in your interpretation so I can verify or correct it. | L5: # CONTEXT I am a business analyst (Business BA). I am working on [PROJECT NAME AND ONE-LINE DESCRIPTION]. My work must respect my organisation's privacy, information-security and data-residency obligations. Everything I paste is de-identified or synthetic — if any input appears to contain real personal or sensitive data, stop and alert me before proceeding. Discovery stage: [NEW INITIATIVE / EXISTING PROBLEM]. What we know so far: [PASTE ANY BRIEFS, EMAILS OR NOTES]. The audience for this output: Business stakeholders and SMEs contributing needs; outputs feed the project brief and requirements backlog. # ACTION Support end-to-end elicitation of business needs and high-level requirements: plan discovery sessions, generate strong questions, convert raw notes into structured needs statements, and expose conflicts and gaps between stakeholders. Support these modes on request: (1) workshop/interview plan with 8-12 questions sequenced broad-to-specific including conflict-testing questions; (2) structure raw notes into business needs statements ('The business needs the ability to [capability] so that [outcome]'); (3) simulate a named stakeholder so I can practise elicitation, then critique which questions I missed. Before drafting, ask me up to 5 clarifying questions about anything missing, then wait for my answers. # RESULT / FORMAT Structured, evidence-based business analysis writing aligned to BABOK good practice. Use clear headings, numbered requirements and tables where they aid scanning. Plain English; expand every acronym on first use; no marketing language. Distinguish clearly between (a) explicit stakeholder statements, (b) implied needs, and (c) items needing clarification, with source attribution. Keep the language professional, plain-English and appropriate for a business audience. Do not invent facts or figures: mark anything you could not verify from my inputs as [TBC] and any value you propose yourself as [PROPOSED — VALIDATE]. Treat the output as a first draft for my review, not a finished artefact. # EXAMPLE Example needs statement I expect: "The business needs the ability to see all open actions for a customer across cases and enquiries in one view, so that staff do not request information the customer has already provided." # VALIDATION (GENERATE → EXPLAIN → TEST) Generate: produce the output requested above. Explain: then break down, step by step, the logic you used to synthesise your answer — how you interpreted each of my inputs and why you structured the output the way you did. Test: list the source references you used for your analysis (my pasted inputs, earlier turns in this conversation, or your general knowledge — label which is which); cross-reference the key facts in your output against those sources and flag anything that does not trace back to a source; and list every additional assumption you made in your interpretation so I can verify or correct it.
A6: BB-02-D1 | B6: Business BA | C6: Business Needs Assessments (Initial and High Level Requirements) | D6: Discovery Workshop Plan & Question Set | E6: Deliverable | F6: Workshop Outputs | G6: I am a business analyst (Business BA). I am working on [PROJECT NAME AND ONE-LINE DESCRIPTION]. My work must respect my organisation's privacy, information-security and data-residency obligations. Everything I paste is de-identified or synthetic — if any input appears to contain real personal or sensitive data, stop and alert me before proceeding. Workshop topic: [TOPIC]. Attendees: [ROLES]. Duration: [LENGTH]. What we already know: [SUMMARY]. The audience for this output: Workshop attendees (agenda) and the facilitating BA (question set and rationale). | H6: Design a discovery workshop that elicits business needs efficiently and surfaces disagreement early. Draft agenda + questions, plus a 'facilitation risks' list (dominant voices, scope drift, sensitive topics such as team performance) with mitigations. Before drafting, ask me up to 5 clarifying questions about anything missing, then wait for my answers. | I6: Timed agenda table; then the question set grouped by theme, sequenced broad-to-specific, each with the rationale and expected output; include at least two questions designed to expose conflicting stakeholder assumptions. Keep the language professional, plain-English and appropriate for a business audience. Do not invent facts or figures: mark anything you could not verify from my inputs as [TBC] and any value you propose yourself as [PROPOSED — VALIDATE]. Treat the output as a first draft for my review, not a finished artefact. | J6: Example question with rationale: "'Walk me through the last time this process went wrong — what happened next?' (Rationale: elicits the real exception path and who is affected; expected output: failure modes for the as-is map.)" | K6: Generate: produce the output requested above. Explain: then break down, step by step, the logic you used to synthesise your answer — how you interpreted each of my inputs and why you structured the output the way you did. Test: list the source references you used for your analysis (my pasted inputs, earlier turns in this conversation, or your general knowledge — label which is which); cross-reference the key facts in your output against those sources and flag anything that does not trace back to a source; and list every additional assumption you made in your interpretation so I can verify or correct it. | L6: # CONTEXT I am a business analyst (Business BA). I am working on [PROJECT NAME AND ONE-LINE DESCRIPTION]. My work must respect my organisation's privacy, information-security and data-residency obligations. Everything I paste is de-identified or synthetic — if any input appears to contain real personal or sensitive data, stop and alert me before proceeding. Workshop topic: [TOPIC]. Attendees: [ROLES]. Duration: [LENGTH]. What we already know: [SUMMARY]. The audience for this output: Workshop attendees (agenda) and the facilitating BA (question set and rationale). # ACTION Design a discovery workshop that elicits business needs efficiently and surfaces disagreement early. Draft agenda + questions, plus a 'facilitation risks' list (dominant voices, scope drift, sensitive topics such as team performance) with mitigations. Before drafting, ask me up to 5 clarifying questions about anything missing, then wait for my answers. # RESULT / FORMAT Timed agenda table; then the question set grouped by theme, sequenced broad-to-specific, each with the rationale and expected output; include at least two questions designed to expose conflicting stakeholder assumptions. Keep the language professional, plain-English and appropriate for a business audience. Do not invent facts or figures: mark anything you could not verify from my inputs as [TBC] and any value you propose yourself as [PROPOSED — VALIDATE]. Treat the output as a first draft for my review, not a finished artefact. # EXAMPLE Example question with rationale: "'Walk me through the last time this process went wrong — what happened next?' (Rationale: elicits the real exception path and who is affected; expected output: failure modes for the as-is map.)" # VALIDATION (GENERATE → EXPLAIN → TEST) Generate: produce the output requested above. Explain: then break down, step by step, the logic you used to synthesise your answer — how you interpreted each of my inputs and why you structured the output the way you did. Test: list the source references you used for your analysis (my pasted inputs, earlier turns in this conversation, or your general knowledge — label which is which); cross-reference the key facts in your output against those sources and flag anything that does not trace back to a source; and list every additional assumption you made in your interpretation so I can verify or correct it.
A7: BB-02-D2 | B7: Business BA | C7: Business Needs Assessments (Initial and High Level Requirements) | D7: Raw Notes → Business Needs Statements | E7: Deliverable | F7: Business Needs Statements; Discovery Notes | G7: I am a business analyst (Business BA). I am working on [PROJECT NAME AND ONE-LINE DESCRIPTION]. My work must respect my organisation's privacy, information-security and data-residency obligations. Everything I paste is de-identified or synthetic — if any input appears to contain real personal or sensitive data, stop and alert me before proceeding. Raw material: [PASTE MEETING NOTES / TRANSCRIPT / EMAIL THREADS]. The audience for this output: Stakeholders who will validate the needs; the delivery team consuming them downstream. | H7: Convert the raw notes into clean, attributed business needs statements ready for validation. Draft the table. Do not invent needs that lack support in the notes — flag gaps instead. Before drafting, ask me up to 5 clarifying questions about anything missing, then wait for my answers. | I7: Table: ID; needs statement ('The business needs the ability to X so that Y'); type (explicit / implied / needs clarification); source (who said it / which note); suggested validation question. Separate section for decisions, actions and parking-lot items. Keep the language professional, plain-English and appropriate for a business audience. Do not invent facts or figures: mark anything you could not verify from my inputs as [TBC] and any value you propose yourself as [PROPOSED — VALIDATE]. Treat the output as a first draft for my review, not a finished artefact. | J7: Example row: "BN-04 | The business needs the ability to lodge service requests from a mobile device so that requests arrive within agreed timeframes | Type: explicit | Source: J. Chen, field ops workshop 12/7 | Validation question: does this extend to third parties without a registered account?" | K7: Generate: produce the output requested above. Explain: then break down, step by step, the logic you used to synthesise your answer — how you interpreted each of my inputs and why you structured the output the way you did. Test: list the source references you used for your analysis (my pasted inputs, earlier turns in this conversation, or your general knowledge — label which is which); cross-reference the key facts in your output against those sources and flag anything that does not trace back to a source; and list every additional assumption you made in your interpretation so I can verify or correct it. | L7: # CONTEXT I am a business analyst (Business BA). I am working on [PROJECT NAME AND ONE-LINE DESCRIPTION]. My work must respect my organisation's privacy, information-security and data-residency obligations. Everything I paste is de-identified or synthetic — if any input appears to contain real personal or sensitive data, stop and alert me before proceeding. Raw material: [PASTE MEETING NOTES / TRANSCRIPT / EMAIL THREADS]. The audience for this output: Stakeholders who will validate the needs; the delivery team consuming them downstream. # ACTION Convert the raw notes into clean, attributed business needs statements ready for validation. Draft the table. Do not invent needs that lack support in the notes — flag gaps instead. Before drafting, ask me up to 5 clarifying questions about anything missing, then wait for my answers. # RESULT / FORMAT Table: ID; needs statement ('The business needs the ability to X so that Y'); type (explicit / implied / needs clarification); source (who said it / which note); suggested validation question. Separate section for decisions, actions and parking-lot items. Keep the language professional, plain-English and appropriate for a business audience. Do not invent facts or figures: mark anything you could not verify from my inputs as [TBC] and any value you propose yourself as [PROPOSED — VALIDATE]. Treat the output as a first draft for my review, not a finished artefact. # EXAMPLE Example row: "BN-04 | The business needs the ability to lodge service requests from a mobile device so that requests arrive within agreed timeframes | Type: explicit | Source: J. Chen, field ops workshop 12/7 | Validation question: does this extend to third parties without a registered account?" # VALIDATION (GENERATE → EXPLAIN → TEST) Generate: produce the output requested above. Explain: then break down, step by step, the logic you used to synthesise your answer — how you interpreted each of my inputs and why you structured the output the way you did. Test: list the source references you used for your analysis (my pasted inputs, earlier turns in this conversation, or your general knowledge — label which is which); cross-reference the key facts in your output against those sources and flag anything that does not trace back to a source; and list every additional assumption you made in your interpretation so I can verify or correct it.
A8: BB-03-M | B8: Business BA | C8: Business Project Discovery & Problem Definition | D8: Master – Discovery & Problem Definition | E8: Master | F8: Problem Statements; Opportunity Assessments; Business Needs Statements; Business Case Inputs; Strategic Alignment Assessments; Risk Assessment Support | G8: I am a business analyst (Business BA). I am working on [PROJECT NAME AND ONE-LINE DESCRIPTION]. My work must respect my organisation's privacy, information-security and data-residency obligations. Everything I paste is de-identified or synthetic — if any input appears to contain real personal or sensitive data, stop and alert me before proceeding. Trigger for this work: [WHAT PROMPTED IT — incident, audit, strategy, pain point]. Known symptoms: [LIST]. Relevant organisational strategic objectives: [PASTE, OR 'NONE SUPPLIED']. The audience for this output: Sponsor, business case authors and investment governance forums. | H8: Help me define the real problem and the case for change: separate symptoms from root causes, quantify impact, frame the opportunity, test strategic alignment, and draft business case inputs and initial risk assessments. Produce on request: (1) a problem statement (situation, impact, magnitude, consequence of inaction); (2) an opportunity assessment with options at a high level; (3) strategic alignment assessment against the organisation's objectives; (4) an initial risk list (risk, cause, consequence, likelihood, impact, mitigation). Before drafting, ask me up to 5 clarifying questions about anything missing, then wait for my answers. | I8: Structured, evidence-based business analysis writing aligned to BABOK good practice. Use clear headings, numbered requirements and tables where they aid scanning. Plain English; expand every acronym on first use; no marketing language. Use the 5 Whys or fishbone technique for causes; every impact claim needs a number or an explicit '[TO BE QUANTIFIED]' flag. Keep the language professional, plain-English and appropriate for a business audience. Do not invent facts or figures: mark anything you could not verify from my inputs as [TBC] and any value you propose yourself as [PROPOSED — VALIDATE]. Treat the output as a first draft for my review, not a finished artefact. | J8: Example problem statement shape: "Customers submitting service requests by phone experience double handling: 40% of requests [TO BE QUANTIFIED] are re-keyed, adding ~3 days delay and creating transcription errors that flow into triage. If unaddressed, timeframe breaches will continue at roughly [X]/quarter." | K8: Generate: produce the output requested above. Explain: then break down, step by step, the logic you used to synthesise your answer — how you interpreted each of my inputs and why you structured the output the way you did. Test: list the source references you used for your analysis (my pasted inputs, earlier turns in this conversation, or your general knowledge — label which is which); cross-reference the key facts in your output against those sources and flag anything that does not trace back to a source; and list every additional assumption you made in your interpretation so I can verify or correct it. | L8: # CONTEXT I am a business analyst (Business BA). I am working on [PROJECT NAME AND ONE-LINE DESCRIPTION]. My work must respect my organisation's privacy, information-security and data-residency obligations. Everything I paste is de-identified or synthetic — if any input appears to contain real personal or sensitive data, stop and alert me before proceeding. Trigger for this work: [WHAT PROMPTED IT — incident, audit, strategy, pain point]. Known symptoms: [LIST]. Relevant organisational strategic objectives: [PASTE, OR 'NONE SUPPLIED']. The audience for this output: Sponsor, business case authors and investment governance forums. # ACTION Help me define the real problem and the case for change: separate symptoms from root causes, quantify impact, frame the opportunity, test strategic alignment, and draft business case inputs and initial risk assessments. Produce on request: (1) a problem statement (situation, impact, magnitude, consequence of inaction); (2) an opportunity assessment with options at a high level; (3) strategic alignment assessment against the organisation's objectives; (4) an initial risk list (risk, cause, consequence, likelihood, impact, mitigation). Before drafting, ask me up to 5 clarifying questions about anything missing, then wait for my answers. # RESULT / FORMAT Structured, evidence-based business analysis writing aligned to BABOK good practice. Use clear headings, numbered requirements and tables where they aid scanning. Plain English; expand every acronym on first use; no marketing language. Use the 5 Whys or fishbone technique for causes; every impact claim needs a number or an explicit '[TO BE QUANTIFIED]' flag. Keep the language professional, plain-English and appropriate for a business audience. Do not invent facts or figures: mark anything you could not verify from my inputs as [TBC] and any value you propose yourself as [PROPOSED — VALIDATE]. Treat the output as a first draft for my review, not a finished artefact. # EXAMPLE Example problem statement shape: "Customers submitting service requests by phone experience double handling: 40% of requests [TO BE QUANTIFIED] are re-keyed, adding ~3 days delay and creating transcription errors that flow into triage. If unaddressed, timeframe breaches will continue at roughly [X]/quarter." # VALIDATION (GENERATE → EXPLAIN → TEST) Generate: produce the output requested above. Explain: then break down, step by step, the logic you used to synthesise your answer — how you interpreted each of my inputs and why you structured the output the way you did. Test: list the source references you used for your analysis (my pasted inputs, earlier turns in this conversation, or your general knowledge — label which is which); cross-reference the key facts in your output against those sources and flag anything that does not trace back to a source; and list every additional assumption you made in your interpretation so I can verify or correct it.
A9: BB-03-D1 | B9: Business BA | C9: Business Project Discovery & Problem Definition | D9: Problem Statement & Opportunity Assessment | E9: Deliverable | F9: Problem Statements; Opportunity Assessments | G9: I am a business analyst (Business BA). I am working on [PROJECT NAME AND ONE-LINE DESCRIPTION]. My work must respect my organisation's privacy, information-security and data-residency obligations. Everything I paste is de-identified or synthetic — if any input appears to contain real personal or sensitive data, stop and alert me before proceeding. Symptoms and evidence gathered so far: [PASTE NOTES, DATA POINTS, COMPLAINTS, AUDIT FINDINGS]. The audience for this output: Sponsor and investment governance. | H9: Produce a sharp problem statement and opportunity assessment that would survive challenge at an investment committee. Apply 5 Whys to my symptoms first and show the chain, then draft both artefacts. Mark every unquantified impact '[TO BE QUANTIFIED]'. Before drafting, ask me up to 5 clarifying questions about anything missing, then wait for my answers. | I9: Problem statement in the format: current situation → who is affected and how often → measurable impact → consequence of doing nothing. Opportunity assessment: 3-4 response options (including 'do nothing') with indicative benefit, cost magnitude, and key risks each. Keep the language professional, plain-English and appropriate for a business audience. Do not invent facts or figures: mark anything you could not verify from my inputs as [TBC] and any value you propose yourself as [PROPOSED — VALIDATE]. Treat the output as a first draft for my review, not a finished artefact. | J9: Example option line: "Option 2 – Guided digital request form with save-and-resume: addresses re-keying at source; indicative benefit: removes ~80% of manual transcription; cost magnitude: medium (existing portal platform); key risk: digital exclusion of smaller customers — mitigation: retain assisted phone channel." | K9: Generate: produce the output requested above. Explain: then break down, step by step, the logic you used to synthesise your answer — how you interpreted each of my inputs and why you structured the output the way you did. Test: list the source references you used for your analysis (my pasted inputs, earlier turns in this conversation, or your general knowledge — label which is which); cross-reference the key facts in your output against those sources and flag anything that does not trace back to a source; and list every additional assumption you made in your interpretation so I can verify or correct it. | L9: # CONTEXT I am a business analyst (Business BA). I am working on [PROJECT NAME AND ONE-LINE DESCRIPTION]. My work must respect my organisation's privacy, information-security and data-residency obligations. Everything I paste is de-identified or synthetic — if any input appears to contain real personal or sensitive data, stop and alert me before proceeding. Symptoms and evidence gathered so far: [PASTE NOTES, DATA POINTS, COMPLAINTS, AUDIT FINDINGS]. The audience for this output: Sponsor and investment governance. # ACTION Produce a sharp problem statement and opportunity assessment that would survive challenge at an investment committee. Apply 5 Whys to my symptoms first and show the chain, then draft both artefacts. Mark every unquantified impact '[TO BE QUANTIFIED]'. Before drafting, ask me up to 5 clarifying questions about anything missing, then wait for my answers. # RESULT / FORMAT Problem statement in the format: current situation → who is affected and how often → measurable impact → consequence of doing nothing. Opportunity assessment: 3-4 response options (including 'do nothing') with indicative benefit, cost magnitude, and key risks each. Keep the language professional, plain-English and appropriate for a business audience. Do not invent facts or figures: mark anything you could not verify from my inputs as [TBC] and any value you propose yourself as [PROPOSED — VALIDATE]. Treat the output as a first draft for my review, not a finished artefact. # EXAMPLE Example option line: "Option 2 – Guided digital request form with save-and-resume: addresses re-keying at source; indicative benefit: removes ~80% of manual transcription; cost magnitude: medium (existing portal platform); key risk: digital exclusion of smaller customers — mitigation: retain assisted phone channel." # VALIDATION (GENERATE → EXPLAIN → TEST) Generate: produce the output requested above. Explain: then break down, step by step, the logic you used to synthesise your answer — how you interpreted each of my inputs and why you structured the output the way you did. Test: list the source references you used for your analysis (my pasted inputs, earlier turns in this conversation, or your general knowledge — label which is which); cross-reference the key facts in your output against those sources and flag anything that does not trace back to a source; and list every additional assumption you made in your interpretation so I can verify or correct it.
A10: BB-03-D2 | B10: Business BA | C10: Business Project Discovery & Problem Definition | D10: Business Case Inputs & Strategic Alignment | E10: Deliverable | F10: Business Case Inputs; Strategic Alignment Assessments | G10: I am a business analyst (Business BA). I am working on [PROJECT NAME AND ONE-LINE DESCRIPTION]. My work must respect my organisation's privacy, information-security and data-residency obligations. Everything I paste is de-identified or synthetic — if any input appears to contain real personal or sensitive data, stop and alert me before proceeding. Problem statement: [PASTE]. Preferred option(s): [PASTE]. Organisational strategic objectives: [PASTE]. The audience for this output: Business case author and finance reviewers. | H10: Draft the BA-owned inputs to the business case: benefits, costs categories, alignment narrative and assumptions. Draft the inputs. Never fabricate dollar figures — provide the structure and mark '[FINANCE TO ESTIMATE]'. Before drafting, ask me up to 5 clarifying questions about anything missing, then wait for my answers. | I10: Sections: benefits table (benefit, type: financial/non-financial, measure, timing); cost categories to be estimated (not invented figures); strategic alignment matrix (objective vs contribution with evidence); assumptions and constraints log. Keep the language professional, plain-English and appropriate for a business audience. Do not invent facts or figures: mark anything you could not verify from my inputs as [TBC] and any value you propose yourself as [PROPOSED — VALIDATE]. Treat the output as a first draft for my review, not a finished artefact. | J10: Example alignment row: "Objective: 'Better client experience' | Contribution: removes duplicate data requests to customers during case handling | Evidence: complaint theme #2 in FY25 voice-of-customer report [PASTE REF] | Strength: direct". | K10: Generate: produce the output requested above. Explain: then break down, step by step, the logic you used to synthesise your answer — how you interpreted each of my inputs and why you structured the output the way you did. Test: list the source references you used for your analysis (my pasted inputs, earlier turns in this conversation, or your general knowledge — label which is which); cross-reference the key facts in your output against those sources and flag anything that does not trace back to a source; and list every additional assumption you made in your interpretation so I can verify or correct it. | L10: # CONTEXT I am a business analyst (Business BA). I am working on [PROJECT NAME AND ONE-LINE DESCRIPTION]. My work must respect my organisation's privacy, information-security and data-residency obligations. Everything I paste is de-identified or synthetic — if any input appears to contain real personal or sensitive data, stop and alert me before proceeding. Problem statement: [PASTE]. Preferred option(s): [PASTE]. Organisational strategic objectives: [PASTE]. The audience for this output: Business case author and finance reviewers. # ACTION Draft the BA-owned inputs to the business case: benefits, costs categories, alignment narrative and assumptions. Draft the inputs. Never fabricate dollar figures — provide the structure and mark '[FINANCE TO ESTIMATE]'. Before drafting, ask me up to 5 clarifying questions about anything missing, then wait for my answers. # RESULT / FORMAT Sections: benefits table (benefit, type: financial/non-financial, measure, timing); cost categories to be estimated (not invented figures); strategic alignment matrix (objective vs contribution with evidence); assumptions and constraints log. Keep the language professional, plain-English and appropriate for a business audience. Do not invent facts or figures: mark anything you could not verify from my inputs as [TBC] and any value you propose yourself as [PROPOSED — VALIDATE]. Treat the output as a first draft for my review, not a finished artefact. # EXAMPLE Example alignment row: "Objective: 'Better client experience' | Contribution: removes duplicate data requests to customers during case handling | Evidence: complaint theme #2 in FY25 voice-of-customer report [PASTE REF] | Strength: direct". # VALIDATION (GENERATE → EXPLAIN → TEST) Generate: produce the output requested above. Explain: then break down, step by step, the logic you used to synthesise your answer — how you interpreted each of my inputs and why you structured the output the way you did. Test: list the source references you used for your analysis (my pasted inputs, earlier turns in this conversation, or your general knowledge — label which is which); cross-reference the key facts in your output against those sources and flag anything that does not trace back to a source; and list every additional assumption you made in your interpretation so I can verify or correct it.
A11: BB-04-M | B11: Business BA | C11: Data & Reporting Analysis | D11: Master – Data & Reporting Analysis | E11: Master | F11: Data Requirements; Data Mapping; Reporting Requirements; KPI Definitions | G11: I am a business analyst (Business BA). I am working on [PROJECT NAME AND ONE-LINE DESCRIPTION]. My work must respect my organisation's privacy, information-security and data-residency obligations. Everything I paste is de-identified or synthetic — if any input appears to contain real personal or sensitive data, stop and alert me before proceeding. Business area and decisions the data must support: [DESCRIBE]. Known source systems: [LIST, e.g. core case management system, billing system, request intake channel, data warehouse]. The audience for this output: Business data owners, reporting teams and the data engineering team. | H11: Define the business data, information and reporting requirements for this initiative: what data is needed, what it means, where it comes from, and what reports and KPIs it must feed. Produce on request: (1) data requirements catalogue (entity, element, business definition, classification incl. personal/health info, quality expectation); (2) source-to-target data mapping tables; (3) reporting requirements (report, purpose, audience, KPIs, dimensions, frequency, access restrictions); (4) KPI definitions; (5) for data warehouse / BI work: a business question catalogue (what/why/how/when/who per question), MECE validation of question themes, business logic and refresh-frequency definitions, and BI technical specification structure (sources, joins, logic — flagged for peer review via validation queries). Before drafting, ask me up to 5 clarifying questions about anything missing, then wait for my answers. | I11: Structured, evidence-based business analysis writing aligned to BABOK good practice. Use clear headings, numbered requirements and tables where they aid scanning. Plain English; expand every acronym on first use; no marketing language. Business language first; add technical detail (types, validation) only after meaning is agreed. Where the data includes personal or otherwise sensitive information, flag the classification per element. Keep the language professional, plain-English and appropriate for a business audience. Do not invent facts or figures: mark anything you could not verify from my inputs as [TBC] and any value you propose yourself as [PROPOSED — VALIDATE]. Treat the output as a first draft for my review, not a finished artefact. | J11: Example element row: "Entity: Request | Element: request_severity | Definition: initial severity band assigned at lodgement (1–4) per triage matrix | Classification: internal | Quality expectation: mandatory at creation, single value, revalidated at assessment". | K11: Generate: produce the output requested above. Explain: then break down, step by step, the logic you used to synthesise your answer — how you interpreted each of my inputs and why you structured the output the way you did. Test: list the source references you used for your analysis (my pasted inputs, earlier turns in this conversation, or your general knowledge — label which is which); cross-reference the key facts in your output against those sources and flag anything that does not trace back to a source; and list every additional assumption you made in your interpretation so I can verify or correct it. | L11: # CONTEXT I am a business analyst (Business BA). I am working on [PROJECT NAME AND ONE-LINE DESCRIPTION]. My work must respect my organisation's privacy, information-security and data-residency obligations. Everything I paste is de-identified or synthetic — if any input appears to contain real personal or sensitive data, stop and alert me before proceeding. Business area and decisions the data must support: [DESCRIBE]. Known source systems: [LIST, e.g. core case management system, billing system, request intake channel, data warehouse]. The audience for this output: Business data owners, reporting teams and the data engineering team. # ACTION Define the business data, information and reporting requirements for this initiative: what data is needed, what it means, where it comes from, and what reports and KPIs it must feed. Produce on request: (1) data requirements catalogue (entity, element, business definition, classification incl. personal/health info, quality expectation); (2) source-to-target data mapping tables; (3) reporting requirements (report, purpose, audience, KPIs, dimensions, frequency, access restrictions); (4) KPI definitions; (5) for data warehouse / BI work: a business question catalogue (what/why/how/when/who per question), MECE validation of question themes, business logic and refresh-frequency definitions, and BI technical specification structure (sources, joins, logic — flagged for peer review via validation queries). Before drafting, ask me up to 5 clarifying questions about anything missing, then wait for my answers. # RESULT / FORMAT Structured, evidence-based business analysis writing aligned to BABOK good practice. Use clear headings, numbered requirements and tables where they aid scanning. Plain English; expand every acronym on first use; no marketing language. Business language first; add technical detail (types, validation) only after meaning is agreed. Where the data includes personal or otherwise sensitive information, flag the classification per element. Keep the language professional, plain-English and appropriate for a business audience. Do not invent facts or figures: mark anything you could not verify from my inputs as [TBC] and any value you propose yourself as [PROPOSED — VALIDATE]. Treat the output as a first draft for my review, not a finished artefact. # EXAMPLE Example element row: "Entity: Request | Element: request_severity | Definition: initial severity band assigned at lodgement (1–4) per triage matrix | Classification: internal | Quality expectation: mandatory at creation, single value, revalidated at assessment". # VALIDATION (GENERATE → EXPLAIN → TEST) Generate: produce the output requested above. Explain: then break down, step by step, the logic you used to synthesise your answer — how you interpreted each of my inputs and why you structured the output the way you did. Test: list the source references you used for your analysis (my pasted inputs, earlier turns in this conversation, or your general knowledge — label which is which); cross-reference the key facts in your output against those sources and flag anything that does not trace back to a source; and list every additional assumption you made in your interpretation so I can verify or correct it.
